#VRML_SIM R2022a utf8
WorldInfo {
}
Viewpoint {
  orientation -0.2267123852764398 -0.14025961220596167 0.9638094913135584 4.216960823857121
  position 0.1660396840686449 0.3225577056475636 0.17976875961242433
}
TexturedBackground {
}
TexturedBackgroundLight {
}
RectangleArena {
  floorSize 3 3
}
Robot {
  translation 0 0 0.0267
  children [
    HingeJoint {
      jointParameters HingeJointParameters {
        anchor -0.05 0 -0.006
      }
      device [
        PositionSensor {
          name "ps2"
        }
        RotationalMotor {
          name "motor2"
        }
      ]
      endPoint Solid {
        translation -0.05 0 -0.006
        rotation -5.851380473311975e-25 1 0 1.57
        children [
          DEF wheel Shape {
            appearance PBRAppearance {
              baseColor 1 0 0
              roughness 1
              metalness 0
            }
            geometry Cylinder {
              height 0.01
              radius 0.02
            }
          }
        ]
        name "Solid(1)"
        boundingObject USE wheel
        physics DEF wheelPhysics Physics {
        }
      }
    }
    DEF Body Transform {
      children [
        Shape {
          appearance PBRAppearance {
            baseColor 0 0 1
            roughness 1
            metalness 0
          }
          geometry Cylinder {
            height 0.05
            radius 0.045
          }
        }
      ]
    }
    HingeJoint {
      jointParameters HingeJointParameters {
        anchor 0.05 0 -0.006
      }
      device [
        PositionSensor {
          name "ps1"
        }
        RotationalMotor {
          name "motor1"
        }
      ]
      endPoint Solid {
        translation 0.05 0 -0.006
        rotation -5.851380473311975e-25 1 0 1.57
        children [
          DEF wheel Shape {
            appearance PBRAppearance {
              baseColor 1 0 0
              roughness 1
              metalness 0
            }
            geometry Cylinder {
              height 0.01
              radius 0.02
            }
          }
        ]
        name "Solid"
        boundingObject USE wheel
        physics DEF wheelPhysics Physics {
        }
      }
    }
  ]
  name "follower"
  boundingObject USE Body
  physics Physics {
  }
  controller "follower"
}
Robot {
  translation -1 0 0.0267
  children [
    HingeJoint {
      jointParameters HingeJointParameters {
        anchor -0.05 0 -0.006
      }
      device [
        PositionSensor {
          name "ps2"
        }
        RotationalMotor {
          name "motor2"
        }
      ]
      endPoint Solid {
        translation -0.05 0 -0.006
        rotation -5.851380473311975e-25 1 0 1.57
        children [
          DEF wheel Shape {
            appearance PBRAppearance {
              baseColor 1 0 0
              roughness 1
              metalness 0
            }
            geometry Cylinder {
              height 0.01
              radius 0.02
            }
          }
        ]
        name "Solid(1)"
        boundingObject USE wheel
        physics DEF wheelPhysics Physics {
        }
      }
    }
    DEF Body Transform {
      children [
        Shape {
          appearance PBRAppearance {
            baseColor 0 1 0
            roughness 1
            metalness 0
          }
          geometry Cylinder {
            height 0.05
            radius 0.045
          }
        }
      ]
    }
    HingeJoint {
      jointParameters HingeJointParameters {
        anchor 0.05 0 -0.006
      }
      device [
        PositionSensor {
          name "ps1"
        }
        RotationalMotor {
          name "motor1"
        }
      ]
      endPoint Solid {
        translation 0.05 0 -0.006
        rotation -5.851380473311975e-25 1 0 1.57
        children [
          DEF wheel Shape {
            appearance PBRAppearance {
              baseColor 1 0 0
              roughness 1
              metalness 0
            }
            geometry Cylinder {
              height 0.01
              radius 0.02
            }
          }
        ]
        name "Solid"
        boundingObject USE wheel
        physics DEF wheelPhysics Physics {
        }
      }
    }
  ]
  name "leader"
  boundingObject USE Body
  physics Physics {
  }
  controller "controlledRobot"
}
